Workbook

Sheet 수강생명단
A2: 아침모의고사 응시자 명단 | H2: 수험번호 찾기( 누적+온라인) | K2: 이름찾기 | N2: 기록 | R2: 메모참고!
A3: 번호 | B3: 연락처 | C3: 수험번호 | D3: 이름 | E3: 기수 | H3: 이름 | I3: 수험번호 | K3: 수험번호 | L3: 이름 | N3: 이름 | O3: 수험번호 | P3: 이름
A4: 1 | B4: 010-5624-8119 | C4: 35357 | D4: 강건욱 | E4: 49 | H4: 오예찬 | I4: =VLOOKUP($H4,$N$4:$O$300,2,FALSE) -> 36028 | K4: 18821 | L4: =VLOOKUP($K4,$O$4:$P$310,2,FALSE) -> 최원석 | N4: 강건욱 | O4: 35357 | P4: 강건욱
A5: 2 | B5: 010-9299-2113 | C5: 33596 | D5: 강동우 | E5: 39 | H5: 권원대 | I5: =VLOOKUP($H5,$N$4:$O$300,2,FALSE) -> 36167 | K5: 21889 | L5: =VLOOKUP($K5,$O$4:$P$310,2,FALSE) -> 이동근 | N5: 강동우 | O5: 33596 | P5: 강동우
A6: 3 | B6: 010-4521-7896 | C6: 32833 | D6: 강민수 | E6: 49 | H6: 최성재 | I6: =VLOOKUP($H6,$N$4:$O$300,2,FALSE) -> 26524 | K6: 22569 | L6: =VLOOKUP($K6,$O$4:$P$310,2,FALSE) -> 김민규 | N6: 강민재 | O6: 34684 | P6: 강민재
A7: 4 | B7: 010-9890-4220 | C7: 34684 | D7: 강민재 | E7: 51 | H7: 문진서 | I7: =VLOOKUP($H7,$N$4:$O$300,2,FALSE) -> 22573 | K7: 22573 | L7: =VLOOKUP($K7,$O$4:$P$310,2,FALSE) -> 문진서 | N7: 강민준 | O7: 32833 | P7: 강민준
A8: 5 | B8: 010-2765-1446 | C8: 41363 | D8: 고건호 | E8: 52 | H8: 심희은 | I8: =VLOOKUP($H8,$N$4:$O$300,2,FALSE) -> 36111 | K8: 22576 | L8: =VLOOKUP($K8,$O$4:$P$310,2,FALSE) -> 유현민 | N8: 고건호 | O8: 41363 | P8: 고건호 | AJ8: 황수빈 | AK8: 0 | AL8: 0
A9: 6 | B9: 010-2449-1632 | C9: 41273 | D9: 고윤솔 | E9: 52 | H9: 김동현 | I9: =VLOOKUP($H9,$N$4:$O$300,2,FALSE) -> 32686 | K9: 22583 | L9: =VLOOKUP($K9,$O$4:$P$310,2,FALSE) -> 김동건 | N9: 고윤솔 | O9: 41273 | P9: 고윤솔 | AJ9: 권나영 | AK9: 0 | AL9: 0
A10: 7 | B10: 010-6267-6869 | C10: 41436 | D10: 고현지 | E10: 52 | H10: 정윤석 | I10: =VLOOKUP($H10,$N$4:$O$300,2,FALSE) -> 26738 | K10: 22594 | L10: =VLOOKUP($K10,$O$4:$P$310,2,FALSE) -> 임진수 | N10: 고현지 | O10: 41436 | P10: 고현지
A11: 8 | B11: 010-2366-4154 | C11: 32975 | D11: 공민준 | E11: 50 | H11: 안서진 | I11: =VLOOKUP($H11,$N$4:$O$300,2,FALSE) -> 28682 | K11: 22606 | L11: =VLOOKUP($K11,$O$4:$P$310,2,FALSE) -> 이근혁 | N11: 공민준 | O11: 32975 | P11: 공민준
A12: 9 | B12: 010-9967-7436 | C12: 31841 | D12: 공초연 | E12: 49 | H12: 최준하 | I12: =VLOOKUP($H12,$N$4:$O$300,2,FALSE) -> 36025 | K12: 22838 | L12: =VLOOKUP($K12,$O$4:$P$310,2,FALSE) -> 배민재 | N12: 공초연 | O12: 31841 | P12: 공초연
A13: 10 | B13: 010-9005-4527 | C13: 32828 | D13: 곽민지 | E13: 49 | H13: 문기환 | I13: =VLOOKUP($H13,$N$4:$O$300,2,FALSE) -> 35951 | K13: 23915 | L13: =VLOOKUP($K13,$O$4:$P$310,2,FALSE) -> 김수빈 | N13: 곽민지 | O13: 32828 | P13: 곽민지
A14: 11 | B14: 010-9910-5290 | C14: 41382 | D14: 곽정민 | E14: 52 | H14: 이수진 | I14: =VLOOKUP($H14,$N$4:$O$300,2,FALSE) -> 36263 | K14: 24108 | L14: =VLOOKUP($K14,$O$4:$P$310,2,FALSE) -> 이승향 | N14: 곽정민 | O14: 41382 | P14: 곽정민
A15: 12 | B15: 010-4318-3133 | C15: 43354 | D15: 구민상 | E15: 52 | H15: 정현지 | I15: =VLOOKUP($H15,$N$4:$O$300,2,FALSE) -> 36472 | K15: 24270 | L15: =VLOOKUP($K15,$O$4:$P$310,2,FALSE) -> 박준우 | N15: 구민상 | O15: 43354 | P15: 구민상
A16: 13 | B16: 010-5181-9377 | C16: 35360 | D16: 구소현 | E16: 49 | H16: 전서준 | I16: =VLOOKUP($H16,$N$4:$O$300,2,FALSE) -> 48537 | K16: 24384 | L16: =VLOOKUP($K16,$O$4:$P$310,2,FALSE) -> 손승효 | N16: 구소현 | O16: 35360 | P16: 구소현
A17: 14 | B17: 010-5210-7936 | C17: 36141 | D17: 권경희 | E17: 51 | H17: 김대호 | I17: =VLOOKUP($H17,$N$4:$O$300,2,FALSE) -> 28700 | K17: 25054 | L17: =VLOOKUP($K17,$O$4:$P$310,2,FALSE) -> 정민겸 | N17: 권경희 | O17: 36141 | P17: 권경희
A18: 15 | B18: 010-8667-4353 | C18: 36169 | D18: 권민재 | E18: 51 | H18: 이동근 | I18: =VLOOKUP($H18,$N$4:$O$300,2,FALSE) -> 21889 | K18: 25104 | L18: =VLOOKUP($K18,$O$4:$P$310,2,FALSE) -> 박나현 | N18: 권민재 | O18: 36169 | P18: 권민재
A19: 16 | B19: 010-9195-0384 | C19: 37133 | D19: 권성준 | E19: 51 | H19: 이근혁 | I19: =VLOOKUP($H19,$N$4:$O$300,2,FALSE) -> 22606 | K19: 25225 | L19: =VLOOKUP($K19,$O$4:$P$310,2,FALSE) -> 박준우A | N19: 권성준 | O19: 37133 | P19: 권성준
A20: 17 | B20: 010-6332-4629 | C20: 36167 | D20: 권원대 | E20: 51 | H20: 황호준 | I20: =VLOOKUP($H20,$N$4:$O$300,2,FALSE) -> 26671 | K20: 25238 | L20: =VLOOKUP($K20,$O$4:$P$310,2,FALSE) -> 김수진 | N20: 권원대 | O20: 36167 | P20: 권원대
A21: 18 | B21: 010-8895-7452 | C21: 41283 | D21: 권태현 | E21: 52 | H21: 이민주 | I21: =VLOOKUP($H21,$N$4:$O$300,2,FALSE) -> 25024 | K21: 25266 | L21: =VLOOKUP($K21,$O$4:$P$310,2,FALSE) -> 박산들 | N21: 권태현 | O21: 41283 | P21: 권태현
... A68: 65 | B68: 010-2672-3483 | C68: 32660 | D68: 김지우 | E68: 49 | H68: 김봉준 | I68: =VLOOKUP($H68,$N$4:$O$300,2,FALSE) -> 21860 | K68: 32828 | L68: =VLOOKUP($K68,$O$4:$P$310,2,FALSE) -> 곽민지 | N68: 김지윤A | O68: 41310 | P68: 김지윤A
A69: 66 | B69: 010-3205-8571 | C69: 41352 | D69: 김지윤 | E69: 52 | I69: =VLOOKUP($H69,$N$4:$O$300,2,FALSE) -> #N/A | K69: 32832 | L69: =VLOOKUP($K69,$O$4:$P$310,2,FALSE) -> 안동규 | N69: 김지현 | O69: 41399 | P69: 김지현
A70: 67 | B70: 010-2796-9616 | C70: 41310 | D70: 김지윤A | E70: 52 | I70: =VLOOKUP($H70,$N$4:$O$300,2,FALSE) -> #N/A | K70: 32833 | L70: =VLOOKUP($K70,$O$4:$P$310,2,FALSE) -> 강민준 | N70: 김진주 | O70: 41347 | P70: 김진주
A71: 68 | B71: 010-7762-1506 | C71: 36071 | D71: 김지윤B | E71: 50 | I71: =VLOOKUP($H71,$N$4:$O$300,2,FALSE) -> #N/A | K71: 32837 | L71: =VLOOKUP($K71,$O$4:$P$310,2,FALSE) -> 서보영 | N71: 김찬엽 | O71: 41375 | P71: 김찬엽
A72: 69 | B72: 010-2423-3648 | C72: 41399 | D72: 김지현 | E72: 52 | I72: =VLOOKUP($H72,$N$4:$O$300,2,FALSE) -> #N/A | K72: 32844 | L72: =VLOOKUP($K72,$O$4:$P$310,2,FALSE) -> 심현석 | N72: 김태현 | O72: 45108 | P72: 김태현
A73: 70 | B73: 010-8132-3150 | C73: 41347 | D73: 김진주 | E73: 52 | I73: =VLOOKUP($H73,$N$4:$O$300,2,FALSE) -> #N/A | K73: 32847 | L73: =VLOOKUP($K73,$O$4:$P$310,2,FALSE) -> 정시은 | N73: 김태훈a | O73: 37298 | P73: 김태훈a
A74: 71 | B74: 010-8405-9831 | C74: 41375 | D74: 김찬엽 | E74: 52 | I74: =VLOOKUP($H74,$N$4:$O$300,2,FALSE) -> #N/A | K74: 32853 | L74: =VLOOKUP($K74,$O$4:$P$310,2,FALSE) -> 김성수 | N74: 김하은 | O74: 41252 | P74: 김하은
A75: 72 | B75: 010-8470-3385 | C75: 45108 | D75: 김태현 | E75: 51 | I75: =VLOOKUP($H75,$N$4:$O$300,2,FALSE) -> #N/A | K75: 32878 | L75: =VLOOKUP($K75,$O$4:$P$310,2,FALSE) -> 이영준 | N75: 김한비 | O75: 32657 | P75: 김한비
A76: 73 | B76: 010-8795-6478 | C76: 37298 | D76: 김태훈A | E76: 32 | I76: =VLOOKUP($H76,$N$4:$O$300,2,FALSE) -> #N/A | K76: 32975 | L76: =VLOOKUP($K76,$O$4:$P$310,2,FALSE) -> 공민준 | N76: 김혜연 | O76: 35971 | P76: 김혜연
A77: 74 | B77: 010-3606-3460 | C77: 41252 | D77: 김하은 | E77: 52 | I77: =VLOOKUP($H77,$N$4:$O$300,2,FALSE) -> #N/A | K77: 32978 | L77: =VLOOKUP($K77,$O$4:$P$310,2,FALSE) -> 전선호 | N77: 남규혁 | O77: 41266 | P77: 남규혁
A78: 75 | B78: 010-6644-8817 | C78: 32657 | D78: 김한비 | E78: 49 | I78: =VLOOKUP($H78,$N$4:$O$300,2,FALSE) -> #N/A | K78: 33000 | L78: =VLOOKUP($K78,$O$4:$P$310,2,FALSE) -> 장예진 | N78: 남동현 | O78: 37313 | P78: 남동현
A79: 76 | B79: 010-8990-2472 | C79: 35971 | D79: 김혜연 | E79: 50 | I79: =VLOOKUP($H79,$N$4:$O$300,2,FALSE) -> #N/A | K79: 33035 | L79: =VLOOKUP($K79,$O$4:$P$310,2,FALSE) -> 박서안 | N79: 노예빈 | O79: 45278 | P79: 노예빈
A80: 77 | B80: 010-8561-5927 | C80: 41266 | D80: 남규혁 | E80: 52 | I80: =VLOOKUP($H80,$N$4:$O$300,2,FALSE) -> #N/A | K80: 33596 | L80: =VLOOKUP($K80,$O$4:$P$310,2,FALSE) -> 강동우 | N80: 노현학 | O80: 28727 | P80: 노현학
... A85: 82 | B85: 010-2888-9707 | C85: 26717 | D85: 류호준 | E85: 48 | I85: =VLOOKUP($H85,$N$4:$O$300,2,FALSE) -> #N/A | K85: 35362 | L85: =VLOOKUP($K85,$O$4:$P$310,2,FALSE) -> 정명수 | N85: 박나현 | O85: 25104 | P85: 박나현
A86: 83 | B86: 010-7267-0889 | C86: 35951 | D86: 문기환 | E86: 일반생 | I86: =VLOOKUP($H86,$N$4:$O$300,2,FALSE) -> #N/A | K86: 35414 | L86: =VLOOKUP($K86,$O$4:$P$310,2,FALSE) -> 이정연A | N86: 박민준 | O86: 38884 | P86: 박민준
A87: 84 | B87: 010-4465-5912 | C87: 22573 | D87: 문진서 | E87: 49 | I87: =VLOOKUP($H87,$N$4:$O$300,2,FALSE) -> #N/A | K87: 35971 | L87: =VLOOKUP($K87,$O$4:$P$310,2,FALSE) -> 김혜연 | N87: 박민철 | O87: 45140 | P87: 박민철
A88: 85 | B88: 010-7523-0446 | C88: 41509 | D88: 민원재 | E88: 일반생 | I88: =VLOOKUP($H88,$N$4:$O$300,2,FALSE) -> #N/A | K88: 35980 | L88: =VLOOKUP($K88,$O$4:$P$310,2,FALSE) -> 김시온 | N88: 박산들 | O88: 25266 | P88: 박산들
A89: 86 | B89: 010-4909-4680 | C89: 26646 | D89: 박근우 | E89: 49 | I89: =VLOOKUP($H89,$N$4:$O$300,2,FALSE) -> #N/A | K89: 35985 | L89: =VLOOKUP($K89,$O$4:$P$310,2,FALSE) -> 윤소영 | N89: 박서안 | O89: 33035 | P89: 박서안
A90: 87 | B90: 010-3683-5983 | C90: 25104 | D90: 박나현 | E90: 49 | I90: =VLOOKUP($H90,$N$4:$O$300,2,FALSE) -> #N/A | K90: 35991 | L90: =VLOOKUP($K90,$O$4:$P$310,2,FALSE) -> 이수민 | N90: 박성민 | O90: 35982 | P90: 박성민
A91: 88 | B91: 010-3425-0802 | C91: 38884 | D91: 박민준 | E91: 41 | I91: =VLOOKUP($H91,$N$4:$O$300,2,FALSE) -> #N/A | K91: 36011 | L91: =VLOOKUP($K91,$O$4:$P$310,2,FALSE) -> 김현우 | N91: 박수석 | O91: 36065 | P91: 박수석
...

Sheet 1주차
A2: 1주차 | AA2: =AC2&"(라)" -> (라) | AB2: 라이브
A4: 헌법 | F4: 형소법 | K4: 형법 | P4: 경찰학 | U4: 주간_앞
A5: 46028 | F5: 46029 | K5: 46031 | P5: 46034
A7: 번호 | B7: 성명 | C7: 객관식 | D7: V.T | F7: 번호 | G7: 성명 | H7: 객관식 | I7: V.T. | K7: 번호 | L7: 성명 | M7: 객관식 | N7: V.T | P7: 번호 | Q7: 성명 | R7: 객관식 | S7: V.T | U7: 번호 | V7: 성명 | W7: 앞면
A8: 18821 | B8: 최원석 | C8: 95 | F8: 41402 | G8: 손한규 | H8: 사유 | K8: 41402 | L8: 손한규 | M8: 사유 | P8: 41402 | Q8: 손한규 | R8: 사유 | S8: 사유
A9: 21889 | B9: 이동근 | C9: 80 | F9: 41361 | G9: 김정윤 | H9: 사유 | K9: 41361 | L9: 김정윤 | M9: 사유 | P9: 41361 | Q9: 김정윤 | R9: 사유 | S9: 사유
A10: 22569 | B10: 김민규 | C10: 80 | F10: 41359 | G10: 이인호 | H10: 사유 | K10: 41359 | L10: 이인호 | M10: 사유
A11: 22576 | B11: 유현민 | C11: 80 | F11: 28690 | G11: 김영서 | H11: 사유 | K11: 28690 | L11: 김영서 | M11: 사유
A12: 22583 | B12: 김동건 | C12: 80 | F12: 18821 | G12: 최원석 | H12: 95 | K12: 28731 | L12: 이가은 | M12: 사유 | P12: 18821 | Q12: 최원석 | R12: 90 | S12: 100
A13: 22594 | B13: 임진수 | C13: 60 | F13: 21889 | G13: 이동근 | H13: 95 | K13: 26599 | L13: 장성민 | M13: 75 | P13: 21889 | Q13: 이동근 | R13: 95 | S13: 90
A14: 22606 | B14: 이근혁 | C14: 90 | F14: 22569 | G14: 김민규 | H14: 95 | K14: 45070 | L14: 조재준 | M14: 90 | P14: 22569 | Q14: 김민규 | R14: 85 | S14: 80
A15: 22838 | B15: 배민재 | C15: 90 | F15: 22583 | G15: 김동건 | H15: 75 | K15: 18821 | L15: 최원석 | M15: 90 | P15: 22573 | Q15: 문진서 | R15: 100 | S15: 90
A16: 23915 | B16: 김수빈 | C16: 40 | F16: 22594 | G16: 임진수 | H16: 90 | K16: 22569 | L16: 김민규 | M16: 95 | P16: 22576 | Q16: 유현민 | R16: 90 | S16: 90
A17: 24108 | B17: 이승향 | C17: 40 | F17: 22606 | G17: 이근혁 | H17: 95 | K17: 22573 | L17: 문진서 | M17: 85 | P17: 22583 | Q17: 김동건 | R17: 80 | S17: 80
A18: 24270 | B18: 박준우 | C18: 65 | F18: 22838 | G18: 배민재 | H18: 75 | K18: 22583 | L18: 김동건 | M18: 85 | P18: 22594 | Q18: 임진수 | R18: 60 | S18: 50
A19: 25054 | B19: 정민겸 | C19: 95 | F19: 23915 | G19: 김수빈 | H19: 60 | K19: 22594 | L19: 임진수 | M19: 80 | P19: 22606 | Q19: 이근혁 | R19: 90 | S19: 100
A20: 25104 | B20: 박나현 | C20: 85 | F20: 24108 | G20: 이승향 | H20: 55 | K20: 23915 | L20: 김수빈 | M20: 65 | P20: 22838 | Q20: 배민재 | R20: 95 | S20: 90
A21: 25238 | B21: 김수진 | C21: 85 | F21: 24270 | G21: 박준우 | H21: 80 | K21: 24108 | L21: 이승향 | M21: 35 | P21: 23915 | Q21: 김수빈 | R21: 40 | S21: 60
A22: 25266 | B22: 박산들 | C22: 95 | F22: 25054 | G22: 정민겸 | H22: 100 | K22: 24270 | L22: 박준우 | M22: 60 | P22: 24108 | Q22: 이승향 | R22: 35 | S22: 50
A23: 25316 | B23: 최원철 | C23: 90 | F23: 25104 | G23: 박나현 | H23: 95 | K23: 25054 | L23: 정민겸 | M23: 100 | P23: 24270 | Q23: 박준우 | R23: 55 | S23: 70
A24: 26455 | B24: 양소은 | C24: 90 | F24: 25225 | G24: 박준우 | H24: 30 | K24: 25104 | L24: 박나현 | M24: 95 | P24: 24384 | Q24: 손승효 | R24: 95 | S24: 80
... A55: 31839 | B55: 이용훈 | C55: 70 | F55: 28731 | G55: 이가은 | H55: 45 | K55: 28747 | L55: 오현기 | M55: 65 | P55: 28720 | Q55: 기지민 | R55: 80 | S55: 100
A56: 31841 | B56: 공초연 | C56: 85 | F56: 28744 | G56: 박현빈 | H56: 45 | K56: 30598 | M56: 90 | P56: 28722 | Q56: 송영서 | R56: 85 | S56: 100
A57: 32026 | B57: 오상수 | C57: 90 | F57: 28747 | G57: 오현기 | H57: 90 | K57: 31374 | L57: 이규호 | M57: 50 | P57: 28727 | Q57: 노현학 | R57: 55 | S57: 100
A58: 32423 | B58: 이광훈 | C58: 80 | F58: 31794 | G58: 최민 | H58: 95 | K58: 31794 | L58: 최민 | M58: 75 | P58: 28731 | Q58: 이가은 | R58: 85 | S58: 80
A59: 32656 | B59: 이서빈 | C59: 60 | F59: 31797 | G59: 김예원 | H59: 95 | K59: 31797 | L59: 김예원 | M59: 95 | P59: 28744 | Q59: 현빈 | R59: 10 | S59: 0
A60: 32657 | B60: 김한비 | C60: 75 | F60: 31836 | G60: 황도현 | H60: 50 | K60: 31839 | L60: 이용훈 | M60: 90 | P60: 28747 | R60: 50 | S60: 80
A61: 32660 | B61: 김지우 | C61: 70 | F61: 31839 | G61: 이용훈 | H61: 95 | K61: 32423 | L61: 이광훈 | M61: 90 | P61: 31794 | Q61: 최민 | R61: 85 | S61: 70
A62: 32664 | B62: 조철희 | C62: 95 | F62: 32423 | G62: 이광훈 | H62: 85 | K62: 32656 | L62: 이서빈 | M62: 100 | P62: 31797 | Q62: 김예원 | R62: 90 | S62: 90
A63: 32676 | B63: 이종화 | C63: 95 | F63: 32656 | G63: 이서빈 | H63: 100 | K63: 32657 | L63: 김한비 | M63: 80 | P63: 31839 | Q63: 이용훈 | R63: 90 | S63: 90
A64: 32677 | B64: 김윤서 | C64: 70 | F64: 32657 | G64: 김한비 | H64: 90 | K64: 32660 | L64: 김지우 | M64: 75 | P64: 32423 | Q64: 이광훈 | R64: 80 | S64: 50
A65: 32684 | B65: 박준형 | C65: 90 | F65: 32660 | G65: 김지우 | H65: 75 | K65: 32676 | L65: 이종화 | M65: 95 | P65: 32647 | Q65: 정원준 | R65: 70 | S65: 80
A66: 32689 | B66: 이효민 | C66: 75 | F66: 32664 | G66: 조철희 | H66: 95 | K66: 32677 | L66: 김윤서 | M66: 90 | P66: 32656 | Q66: 이서빈 | R66: 80 | S66: 100
A67: 32807 | B67: 장윤정 | C67: 60 | F67: 32676 | G67: 이종화 | H67: 100 | K67: 32684 | L67: 박준형 | M67: 80 | P67: 32657 | Q67: 김한비 | R67: 85 | S67: 70
A68: 32808 | B68: 이영승 | C68: 75 | F68: 32677 | G68: 김윤서 | H68: 85 | K68: 32689 | L68: 이효민 | M68: 95 | P68: 32660 | Q68: 김지우 | R68: 95 | S68: 70
A69: 32828 | B69: 곽민지 | C69: 85 | F69: 32684 | G69: 박준형 | H69: 95 | K69: 32807 | L69: 장윤정 | M69: 55 | P69: 32664 | Q69: 조철희 | R69: 90 | S69: 100
A70: 32832 | B70: 안동규 | C70: 75 | F70: 32689 | G70: 이효민 | H70: 95 | K70: 32808 | L70: 이얭승 | M70: 75 | P70: 32676 | Q70: 이종화 | R70: 100 | S70: 100
A71: 32833 | B71: 강민수 | C71: 100 | F71: 32807 | G71: 장윤정 | H71: 75 | K71: 32828 | L71: 곽민지 | M71: 85 | P71: 32677 | Q71: 김윤서 | R71: 75 | S71: 70
A72: 32837 | B72: 서보영 | C72: 95 | F72: 32808 | G72: 이영승 | H72: 65 | K72: 32832 | L72: 안동규 | M72: 95 | P72: 32684 | Q72: 박준형 | R72: 100 | S72: 80
... A89: 36019 | B89: 이재욱 | C89: 100 | F89: 35192 | G89: 박인혜 | H89: 70 | K89: 35980 | L89: 김시온 | M89: 100 | P89: 33717 | Q89: 최상덕 | R89: 40 | S89: 80
...

Sheet 2주차
A2: 2주차 | AM2: =AO2&"(라)" -> (라) | AN2: 라이브
A4: 헌법 | F4: 형소법 | K4: 형법 | P4: 경찰학 | U4: 형법 | Z4: 경찰학 | AF4: 누적
A7: 번호 | B7: 성명 | C7: 객관식 | D7: ox | F7: 번호 | G7: 성명 | H7: 객관식 | I7: ox | K7: 번호 | L7: 성명 | M7: 객관식 | N7: V.T | P7: 번호 | Q7: 성명 | R7: 객관식 | S7: V.T | U7: 번호 | V7: 성명 | W7: 객관식 | X7: ox | Z7: 번호 | AA7: 성명 | AB7: 객관식 | AC7: ox | AF7: 번호 | AG7: 성명 | AH7: 성적
A8: 18821 | B8: 최원석 | C8: 95 | D8: 90 | F8: 18821 | G8: 최원석 | H8: 95 | I8: 90
A9: 22569 | B9: 김민규 | C9: 75 | D9: 90 | F9: 22569 | H9: 100 | I9: 90 | U9: 41361 | V9: 김정윤 | W9: 사유 | X9: 사유 | Z9: 26455 | AA9: 양소은 | AB9: 사유 | AC9: 사유 | AF9: 41361 | AG9: 41361 | AH9: 사유
A10: 22573 | B10: 문진서 | C10: 85 | D10: 100 | F10: 22573 | G10: 문진서 | H10: 100 | I10: 100 | U10: 41402 | V10: 손한규 | W10: 사유 | X10: 사유 | Z10: 41402 | AA10: 손한규 | AB10: 사유 | AC10: 사유 | AF10: 41402 | AG10: 41402 | AH10: 사유
A11: 22576 | C11: 90 | D11: 90 | F11: 22583 | G11: 김동건 | H11: 90 | I11: 0 | U11: 18821 | V11: 최원석 | W11: 65 | X11: 70 | Z11: 18821 | AA11: 최원석 | AB11: 70 | AC11: 60 | AF11: 41394 | AG11: 41394 | AH11: 사유
A12: 22583 | B12: 김동건 | C12: 80 | D12: 0 | F12: 22594 | G12: 임진수 | H12: 75 | I12: 60 | U12: 22569 | V12: 김민규 | W12: 85 | X12: 90 | Z12: 28744 | AA12: 박현빈 | AB12: 40 | AC12: 0 | AF12: 18821 | AG12: 18821 | AH12: 98
A13: 22594 | B13: 임진수 | C13: 75 | D13: 90 | F13: 22606 | G13: 이근혁 | H13: 90 | I13: 100 | U13: 22573 | V13: 문진서 | W13: 95 | X13: 90 | Z13: 22569 | AA13: 김민규 | AB13: 85 | AC13: 80 | AF13: 22569 | AG13: 22569 | AH13: 95
A14: 22606 | B14: 이근혁 | C14: 90 | D14: 100 | F14: 22838 | G14: 배민재 | H14: 85 | I14: 90 | U14: 22583 | V14: 김동건 | W14: 60 | X14: 0 | Z14: 22573 | AA14: 문진서 | AB14: 95 | AC14: 100 | AF14: 22573 | AG14: 22573 | AH14: 93
A15: 22838 | B15: 배민재 | C15: 85 | D15: 100 | F15: 23915 | G15: 김수빈 | H15: 55 | I15: 60 | U15: 22594 | V15: 임진수 | W15: 50 | X15: 70 | Z15: 22576 | AA15: 유현민 | AB15: 95 | AC15: 70 | AF15: 22583 | AG15: 22583 | AH15: 92
A16: 23915 | B16: 김수빈 | C16: 55 | D16: 70 | F16: 24108 | G16: 이승향 | H16: 55 | I16: 50 | U16: 22606 | V16: 이근혁 | W16: 85 | X16: 90 | Z16: 22583 | AA16: 김동건 | AB16: 80 | AC16: 0 | AF16: 22594 | AG16: 22594 | AH16: 77
A17: 24108 | B17: 이승향 | C17: 55 | D17: 0 | F17: 24270 | G17: 박준우 | H17: 65 | I17: 30 | U17: 22838 | V17: 배민재 | W17: 95 | X17: 100 | Z17: 22594 | AA17: 임진수 | AB17: 35 | AC17: 60 | AF17: 22838 | AG17: 22838 | AH17: 96
A18: 24270 | B18: 박준우 | C18: 60 | D18: 80 | F18: 24384 | G18: 손승효 | H18: 100 | I18: 100 | U18: 23915 | V18: 김수빈 | W18: 45 | X18: 40 | Z18: 22838 | AA18: 배민재 | AB18: 90 | AC18: 60 | AF18: 23915 | AG18: 23915 | AH18: 67
A19: 24384 | B19: 손승효 | C19: 95 | D19: 100 | F19: 25054 | G19: 정민겸 | H19: 100 | I19: 80 | U19: 24108 | V19: 이승향 | W19: 15 | X19: 40 | Z19: 23915 | AA19: 김수빈 | AB19: 45 | AC19: 50 | AF19: 24270 | AG19: 24270 | AH19: 80
A20: 25054 | B20: 정민겸 | C20: 95 | D20: 100 | F20: 25104 | G20: 박나현 | H20: 100 | I20: 90 | U20: 24270 | V20: 박준우 | W20: 55 | X20: 40 | Z20: 24108 | AA20: 이승향 | AB20: 20 | AC20: 50 | AF20: 25054 | AG20: 25054 | AH20: 98
A21: 25104 | B21: 박나현 | C21: 85 | D21: 100 | F21: 25225 | G21: 박준우 | H21: 45 | I21: 40 | U21: 25054 | V21: 정민겸 | W21: 95 | X21: 0 | Z21: 24270 | AA21: 박준우 | AB21: 45 | AC21: 40 | AF21: 25225 | AG21: 25225 | AH21: 38
A22: 25238 | B22: 김수진 | C22: 75 | D22: 80 | F22: 25238 | G22: 김수진 | H22: 80 | I22: 90 | U22: 25104 | V22: 박나현 | W22: 80 | X22: 80 | Z22: 25054 | AA22: 정민겸 | AB22: 85 | AC22: 80 | AF22: 25316 | AG22: 25316 | AH22: 96
A23: 25316 | B23: 최원철 | C23: 95 | D23: 100 | F23: 25316 | G23: 최원철 | H23: 90 | I23: 90 | U23: 25225 | V23: 박준우A | W23: 25 | X23: 30 | Z23: 25104 | AA23: 박나현 | AB23: 75 | AC23: 100 | AF23: 26455 | AG23: 26455 | AH23: 98
... A27: 26574 | B27: 류하온 | C27: 70 | D27: 100 | F27: 26574 | G27: 류하온 | H27: 75 | I27: 100 | U27: 26574 | V27: 류하온 | W27: 40 | X27: 80 | Z27: 26562 | AA27: 하채영 | AB27: 85 | AC27: 70 | AF27: 26599 | AG27: 26599 | AH27: 87
A28: 26575 | C28: 95 | D28: 90 | F28: 26599 | G28: 장성민 | H28: 95 | I28: 90 | U28: 26575 | V28: 이동건 | W28: 70 | X28: 70 | Z28: 26575 | AA28: 이동건 | AB28: 70 | AC28: 90 | AF28: 26646 | AG28: 26646 | AH28: 87
A29: 26599 | B29: 장성민 | C29: 90 | D29: 80 | F29: 26646 | G29: 박근우 | H29: 95 | I29: 80 | U29: 26599 | V29: 장성민 | W29: 65 | X29: 80 | Z29: 26599 | AA29: 장성민 | AB29: 75 | AC29: 90 | AF29: 26657 | AG29: 26657 | AH29: 65
A30: 26646 | B30: 박근우 | C30: 90 | D30: 90 | F30: 26657 | G30: 유해강 | H30: 50 | I30: 60 | U30: 26646 | V30: 박근우 | W30: 70 | X30: 70 | Z30: 26713 | AA30: 유다경 | AB30: 45 | AC30: 60 | AF30: 26713 | AG30: 26713 | AH30: 88
A31: 26657 | B31: 유해강 | C31: 75 | D31: 60 | F31: 26713 | G31: 유다경 | H31: 75 | I31: 80 | U31: 26657 | V31: 유해강 | W31: 30 | X31: 30 | Z31: 26718 | AA31: 이지훈 | AB31: 20 | AC31: 40 | AF31: 26718 | AG31: 26718 | AH31: 57
A32: 26713 | B32: 유다경 | C32: 75 | D32: 90 | F32: 26718 | G32: 이지훈 | H32: 35 | I32: 40 | U32: 26713 | V32: 유다경 | W32: 40 | X32: 40 | Z32: 26801 | AA32: 김아진 | AB32: 90 | AC32: 100 | AF32: 26736 | AG32: 26736 | AH32: 91
A33: 26718 | B33: 이지훈 | C33: 25 | D33: 50 | F33: 26895 | G33: 현승민 | H33: 55 | I33: 50 | U33: 26718 | V33: 이지훈 | W33: 25 | X33: 30 | Z33: 26895 | AA33: 현승민 | AB33: 45 | AC33: 50 | AF33: 26801 | AG33: 26801 | AH33: 91
A34: 26736 | B34: 하정석 | C34: 85 | D34: 80 | F34: 26935 | G34: 전재민 | H34: 95 | I34: 80 | U34: 26801 | V34: 김아진 | W34: 85 | X34: 70 | Z34: 26935 | AA34: 전재민 | AB34: 80 | AC34: 90 | AF34: 26895 | AG34: 26895 | AH34: 80
A35: 26895 | B35: 현승민 | C35: 45 | D35: 50 | F35: 28679 | G35: 박지호 | H35: 55 | I35: 70 | U35: 26895 | V35: 현승민 | W35: 45 | X35: 40 | Z35: 28679 | AA35: 박지호 | AB35: 35 | AC35: 50 | AF35: 26935 | AG35: 26935 | AH35: 92
A36: 26935 | B36: 전재민 | C36: 100 | D36: 100 | F36: 28682 | G36: 안서진 | H36: 90 | I36: 70 | U36: 26935 | V36: 전재민 | W36: 85 | X36: 100 | Z36: 28682 | AA36: 안서진 | AB36: 45 | AC36: 50 | AF36: 28679 | AG36: 28679 | AH36: 63
A37: 28679 | B37: 박지호 | C37: 55 | D37: 60 | F37: 28686 | G37: 원예정 | H37: 90 | I37: 80 | U37: 28679 | V37: 박지호 | W37: 50 | X37: 50 | Z37: 28686 | AA37: 원예정 | AB37: 60 | AC37: 80 | AF37: 28682 | AG37: 28682 | AH37: 88
A38: 28682 | B38: 안서진 | C38: 80 | D38: 90 | F38: 28689 | G38: 윤종녕 | H38: 55 | I38: 70 | U38: 28682 | V38: 안서진 | W38: 55 | X38: 40 | Z38: 28689 | AA38: 윤종녕 | AB38: 70 | AC38: 60 | AF38: 28686 | AG38: 28686 | AH38: 94
A39: 28686 | B39: 원예정 | C39: 85 | D39: 80 | F39: 28690 | G39: 김영서 | H39: 60 | I39: 60 | U39: 28686 | V39: 원예정 | W39: 60 | X39: 80 | Z39: 28690 | AA39: 김영서 | AB39: 50 | AC39: 40 | AF39: 28689 | AG39: 28689 | AH39: 88
A40: 28688 | B40: 박채원 | C40: 60 | D40: 50 | F40: 28692 | G40: 배석현 | H40: 60 | I40: 80 | U40: 28689 | V40: 윤종녕 | W40: 65 | X40: 50 | Z40: 28700 | AA40: 김대호 | AB40: 35 | AC40: 60 | AF40: 28690 | AG40: 28690 | AH40: 71
... A179: 45053 | B179: 송치원 | C179: 95 | D179: 90 | F179: 45046 | G179: 방민호 | H179: 85 | I179: 100 | U179: 45083 | V179: 송수민 | W179: 75 | X179: 90 | Z179: 45080 | AA179: 김유선 | AB179: 95 | AC179: 60 | AF179: 45118 | AG179: 45118 | AH179: 89
A180: 45057 | C180: 55 | D180: 80 | F180: 45057 | H180: 80 | I180: 60 | U180: 45088 | V180: 우지원 | W180: 50 | X180: 70 | Z180: 45081 | AA180: 박정민 | AB180: 95 | AC180: 100 | AF180: 45120 | AG180: 45120 | AH180: 91
A181: 45061 | B181: 박윤정 | C181: 100 | D181: 100 | F181: 45061 | G181: 박윤정 | H181: 95 | I181: 70 | U181: 45118 | V181: 조용민 | W181: 45 | X181: 30 | Z181: 45083 | AA181: 송수민 | AB181: 60 | AC181: 80 | AF181: 45122 | AG181: 45122 | AH181: 99
A182: 45062 | B182: 김건형 | C182: 95 | D182: 100 | F182: 45062 | G182: 김건형 | H182: 95 | I182: 80 | U182: 45120 | V182: 양수황 | W182: 70 | X182: 70 | Z182: 45086 | AA182: 박찬호 | AB182: 40 | AC182: 60 | AF182: 45130 | AG182: 45130 | AH182: 86
A183: 45064 | B183: 김다빈 | C183: 90 | D183: 100 | F183: 45064 | G183: 김다빈 | H183: 75 | I183: 50 | U183: 45122 | V183: 윤수빈 | W183: 65 | X183: 40 | Z183: 45088 | AA183: 우지원 | AB183: 40 | AC183: 60 | AF183: 45140 | AG183: 45140 | AH183: 96
A184: 45066 | B184: 정현우 | C184: 60 | D184: 80 | F184: 45066 | G184: 정현우 | H184: 85 | I184: 70 | U184: 45130 | V184: 배혜빈 | W184: 30 | X184: 30 | Z184: 45118 | AA184: 조용민 | AB184: 35 | AC184: 70 | AF184: 45278 | AG184: 45278 | AH184: 99
A185: 45068 | B185: 서희주 | C185: 60 | D185: 90 | F185: 45068 | G185: 서희주 | H185: 95 | I185: 80 | U185: 45140 | V185: 박민철 | W185: 75 | X185: 80 | Z185: 45120 | AA185: 양수황 | AB185: 65 | AC185: 70 | AF185: 45551 | AG185: 45551 | AH185: 99
...

Sheet 3주차
A2: 3주차
A4: 헌법 | F4: 형소법 | K4: 형법 | P4: 경찰학 | V4: 누적모의고사 | AB4: =AD4&"(라)" -> (라) | AC4: 라이브
A5: 46042 | F5: 46043 | K5: 46045 | P5: 46048 | V5: 46044
A7: 번호 | B7: 성명 | C7: 객관식 | D7: ox | F7: 번호 | G7: 성명 | H7: 객관식 | I7: ox | K7: 번호 | L7: 성명 | M7: 객관식 | N7: ox | P7: 번호 | Q7: 성명 | R7: 객관식 | S7: ox | V7: 수험번호 | W7: 수험번호 | X7: 점수
A9: 41435 | B9: 이창건 | C9: 사유 | D9: 사유 | F9: 41491 | G9: 김영운 | H9: 탈락 | I9: 탈락 | K9: 41491 | L9: 김영운 | M9: 탈락 | N9: 탈락 | P9: 41491 | Q9: 김영운 | R9: 탈락 | S9: 탈락 | V9: 41491 | W9: 41491 | X9: 탈락
A10: 18821 | B10: 최원석 | C10: 90 | D10: 100 | F10: 36030 | G10: 김준경 | H10: 탈락 | I10: 탈락 | K10: 36030 | L10: 김준경 | M10: 탈락 | N10: 탈락 | P10: 36030 | Q10: 김준경 | R10: 탈락 | S10: 탈락 | V10: 36030 | W10: 36030 | X10: 탈락
A11: 22569 | B11: 김민규 | C11: 75 | D11: 90 | F11: 41509 | G11: 민원재 | H11: 탈락 | I11: 탈락 | K11: 41509 | L11: 민원재 | M11: 탈락 | N11: 탈락 | P11: 41509 | Q11: 민원재 | R11: 탈락 | S11: 탈락 | V11: 41509 | W11: 41509 | X11: 탈락
A12: 22573 | B12: 문진서 | C12: 75 | D12: 100 | F12: 28688 | G12: 박채원 | H12: 탈락 | I12: 탈락 | K12: 28688 | L12: 박채원 | M12: 탈락 | N12: 탈락 | P12: 28688 | Q12: 박채원 | R12: 탈락 | S12: 탈락 | V12: 28688 | W12: 28688 | X12: 탈락
A13: 22583 | B13: 김동건 | C13: 85 | D13: 100 | F13: 31278 | G13: 박회근 | H13: 탈락 | I13: 탈락 | K13: 31278 | L13: 박회근 | M13: 탈락 | N13: 탈락 | P13: 31278 | Q13: 박회근 | R13: 탈락 | S13: 탈락 | V13: 31278 | W13: 31278 | X13: 탈락
A14: 22594 | B14: 임진수 | C14: 55 | D14: 80 | F14: 28692 | G14: 배석현 | H14: 탈락 | I14: 탈락 | K14: 28692 | L14: 배석현 | M14: 탈락 | N14: 탈락 | P14: 28692 | Q14: 배석현 | R14: 탈락 | S14: 탈락 | V14: 28692 | W14: 28692 | X14: 탈락
A15: 22838 | B15: 배민재 | C15: 85 | D15: 80 | F15: 36145 | G15: 윤현진 | H15: 탈락 | I15: 탈락 | K15: 36145 | L15: 윤현진 | M15: 탈락 | N15: 탈락 | P15: 36145 | Q15: 윤현진 | R15: 탈락 | S15: 탈락 | V15: 36145 | W15: 36145 | X15: 탈락
A16: 23915 | B16: 김수빈 | C16: 65 | D16: 60 | F16: 21889 | G16: 이동근 | H16: 탈락 | I16: 탈락 | K16: 21889 | L16: 이동근 | M16: 탈락 | N16: 탈락 | V16: 21889 | W16: 21889 | X16: 탈락
A17: 24108 | B17: 이승향 | C17: 35 | D17: 50 | F17: 39058 | G17: 이상훈 | H17: 탈락 | I17: 탈락 | K17: 39058 | L17: 이상훈 | M17: 탈락 | N17: 탈락 | P17: 39058 | Q17: 이상훈 | R17: 탈락 | S17: 탈락 | V17: 39058 | W17: 39058 | X17: 탈락
A18: 24270 | B18: 박준우 | C18: 70 | D18: 100 | F18: 36420 | G18: 이수왕 | H18: 탈락 | I18: 탈락 | K18: 36420 | L18: 이수왕 | M18: 탈락 | N18: 탈락 | P18: 36420 | Q18: 이수왕 | R18: 탈락 | S18: 탈락 | V18: 36420 | W18: 36420 | X18: 탈락
A19: 25054 | B19: 졍민겸 | C19: 85 | D19: 100 | F19: 33717 | G19: 최상덕 | H19: 탈락 | I19: 탈락 | K19: 33717 | L19: 최상덕 | M19: 탈락 | N19: 탈락 | P19: 33717 | Q19: 최상덕 | R19: 탈락 | S19: 탈락 | V19: 33717 | W19: 33717 | X19: 탈락
A20: 25104 | B20: 박나현 | C20: 75 | D20: 100 | F20: 41388 | G20: 최승호 | H20: 탈락 | I20: 탈락 | K20: 41388 | L20: 최승호 | M20: 탈락 | N20: 탈락 | P20: 41388 | Q20: 최승호 | R20: 탈락 | S20: 탈락 | V20: 41388 | W20: 41388 | X20: 탈락
A21: 25238 | B21: 김수진 | C21: 80 | D21: 90 | F21: 26627 | G21: 최진호 | H21: 탈락 | I21: 탈락 | K21: 26627 | L21: 최진호 | M21: 탈락 | N21: 탈락 | P21: 26627 | Q21: 최진호 | R21: 탈락 | S21: 탈락 | V21: 26627 | W21: 26627 | X21: 탈락
A22: 25266 | B22: 박산들 | C22: 90 | D22: 100 | F22: 18821 | G22: 최원석 | H22: 95 | I22: 90 | K22: 37128 | L22: 이승희 | M22: 사유 | N22: 사유 | P22: 18821 | Q22: 최원석 | R22: 80 | S22: 80 | V22: 28744 | W22: 28744 | X22: 사유
A23: 25316 | B23: 최원철 | C23: 90 | D23: 100 | F23: 22569 | G23: 김민규 | H23: 90 | I23: 90 | K23: 41436 | L23: 고현지 | M23: 사유 | N23: 사유 | P23: 21889 | Q23: 이동근 | R23: 90 | S23: 80 | V23: 18821 | W23: 18821 | X23: 98
A24: 26455 | B24: 양소은 | C24: 90 | D24: 100 | F24: 22573 | G24: 문진서 | H24: 90 | I24: 80 | K24: 31797 | L24: 김예원 | M24: 95 | N24: 100 | P24: 22569 | Q24: 김민규 | R24: 80 | S24: 100 | V24: 22569 | W24: 22569 | X24: 93
A25: 26562 | B25: 하채영 | C25: 90 | D25: 100 | F25: 22594 | G25: 임진수 | H25: 65 | I25: 40 | K25: 22569 | L25: 김민규 | M25: 80 | N25: 100 | P25: 22573 | Q25: 문진서 | R25: 95 | S25: 90 | V25: 22573 | W25: 22573 | X25: 96
A26: 26574 | B26: 류하온 | C26: 60 | D26: 90 | F26: 22838 | G26: 배민재 | H26: 90 | I26: 100 | K26: 22573 | L26: 문진서 | M26: 95 | N26: 90 | P26: 22583 | Q26: 김동건 | R26: 90 | S26: 0 | V26: 22576 | W26: 22576 | X26: 48
A27: 26599 | B27: 장성민 | C27: 60 | D27: 100 | F27: 23915 | G27: 김수빈 | H27: 55 | I27: 20 | K27: 22576 | L27: 유현민 | M27: 95 | N27: 90 | P27: 22838 | Q27: 배민재 | R27: 100 | S27: 100 | V27: 22583 | W27: 22583 | X27: 92
A28: 26646 | B28: 박근우 | C28: 85 | D28: 90 | F28: 24108 | G28: 이승향 | H28: 50 | I28: 70 | K28: 22583 | L28: 김동건 | M28: 95 | N28: 70 | P28: 23915 | Q28: 김수빈 | R28: 35 | S28: 80 | V28: 22594 | W28: 22594 | X28: 68
A29: 26657 | B29: 유해강 | C29: 65 | D29: 90 | F29: 24270 | G29: 박준우 | H29: 55 | I29: 60 | K29: 22594 | L29: 임진수 | M29: 70 | N29: 30 | P29: 24108 | Q29: 이승향 | R29: 25 | S29: 40 | V29: 22838 | W29: 22838 | X29: 99
A30: 26713 | B30: 유다경 | C30: 85 | D30: 90 | F30: 24384 | G30: 손승효 | H30: 95 | I30: 100 | K30: 22838 | L30: 배민재 | M30: 95 | N30: 90 | P30: 24270 | Q30: 박준우 | R30: 35 | S30: 70 | V30: 23915 | W30: 23915 | X30: 74
A31: 26718 | B31: 이지훈 | C31: 35 | D31: 50 | F31: 25054 | G31: 정민겸 | H31: 95 | I31: 70 | K31: 23915 | L31: 김수빈 | M31: 50 | N31: 50 | P31: 24384 | Q31: 손승효 | R31: 100 | S31: 100 | V31: 24108 | W31: 24108 | X31: 58
A32: 26736 | B32: 하정석 | C32: 85 | D32: 90 | F32: 25104 | G32: 박나현 | H32: 85 | I32: 80 | K32: 24108 | L32: 이승향 | M32: 50 | N32: 40 | P32: 25054 | Q32: 정민겸 | R32: 80 | S32: 90 | V32: 24270 | W32: 24270 | X32: 76
A33: 26895 | B33: 현승민 | C33: 50 | D33: 80 | F33: 25225 | G33: 박준우 | H33: 30 | I33: 30 | K33: 24270 | L33: 박준우 | M33: 50 | N33: 60 | P33: 25104 | Q33: 박나현 | R33: 95 | S33: 90 | V33: 25054 | W33: 25054 | X33: 99
A34: 26935 | B34: 전재민 | C34: 85 | D34: 100 | F34: 25266 | G34: 박산들 | H34: 90 | I34: 100 | K34: 24384 | L34: 손승효 | M34: 100 | N34: 100 | P34: 25225 | Q34: 박준우 | R34: 35 | S34: 50 | V34: 25225 | W34: 25225 | X34: 40
A35: 28679 | B35: 박지호 | C35: 40 | D35: 60 | F35: 26455 | G35: 양소은 | H35: 90 | I35: 70 | K35: 25054 | L35: 정민겸 | M35: 85 | N35: 90 | P35: 25238 | Q35: 김수진 | R35: 75 | S35: 100 | V35: 25316 | W35: 25316 | X35: 95
... A44: 28715 | B44: 김종서 | C44: 35 | D44: 50 | F44: 28679 | G44: 박지호 | H44: 75 | I44: 70 | K44: 26574 | L44: 류하온 | M44: 65 | N44: 90 | P44: 26718 | Q44: 이지훈 | R44: 25 | S44: 70 | V44: 26801 | W44: 26801 | X44: 93
A45: 28719 | B45: 유성윤 | C45: 60 | D45: 90 | F45: 28682 | G45: 안서진 | H45: 65 | I45: 60 | K45: 26575 | M45: 100 | N45: 70 | P45: 26801 | Q45: 김아진 | R45: 90 | S45: 90 | V45: 26895 | W45: 26895 | X45: 70
A46: 28720 | B46: 기지민 | C46: 70 | D46: 100 | F46: 28686 | G46: 원예정 | H46: 90 | I46: 80 | K46: 26599 | L46: 장성민 | M46: 80 | N46: 90 | P46: 26895 | Q46: 현승민 | R46: 35 | S46: 70 | V46: 28679 | W46: 28679 | X46: 66
A47: 28722 | B47: 송영서 | C47: 95 | D47: 100 | F47: 28689 | G47: 윤종녕 | H47: 90 | I47: 90 | K47: 26646 | L47: 박근우 | M47: 85 | N47: 100 | P47: 26935 | Q47: 전재민 | R47: 85 | S47: 100 | V47: 28682 | W47: 28682 | X47: 69
A48: 28727 | B48: 노현학 | C48: 85 | D48: 90 | F48: 28690 | G48: 김영서 | H48: 55 | I48: 80 | K48: 26657 | L48: 유해강 | M48: 25 | N48: 60 | P48: 28679 | Q48: 박지호 | R48: 30 | S48: 40 | V48: 28686 | W48: 28686 | X48: 92
A49: 28729 | B49: 홍승원 | C49: 90 | D49: 70 | F49: 28700 | G49: 김대호 | H49: 75 | I49: 90 | K49: 26713 | L49: 유다경 | M49: 70 | N49: 60 | P49: 28686 | Q49: 원예정 | R49: 70 | S49: 80 | V49: 28689 | W49: 28689 | X49: 89
A50: 28731 | B50: 이가은 | C50: 85 | D50: 80 | F50: 28701 | G50: 정승화 | H50: 55 | I50: 10 | K50: 26718 | L50: 이지훈 | M50: 40 | N50: 50 | P50: 28689 | Q50: 윤종녕 | R50: 35 | S50: 90 | V50: 28690 | W50: 28690 | X50: 87
A51: 28744 | B51: 박현빈 | C51: 35 | D51: 0 | F51: 28702 | G51: 윤대현 | H51: 95 | I51: 90 | K51: 26801 | L51: 김아진 | M51: 75 | N51: 100 | P51: 28701 | Q51: 정승화 | R51: 65 | S51: 60 | V51: 28700 | W51: 28700 | X51: 88
A52: 31794 | B52: 최민 | C52: 65 | D52: 90 | F52: 28703 | G52: 정해린 | H52: 70 | I52: 60 | K52: 26895 | L52: 현승민 | M52: 50 | N52: 70 | P52: 28702 | Q52: 윤대현 | R52: 60 | S52: 80 | V52: 28701 | W52: 28701 | X52: 83
...

Sheet 4주차
A2: 4주차 | AA2: =AC2&"(라)" -> (라) | AB2: 라이브
A4: 헌법 | F4: 형소법 | K4: 형법 | P4: 경찰학 | V4: 누적모의고사
A7: 수험번호 | B7: 성명 | C7: 객관식 | D7: ox | F7: 수험번호 | G7: 성명 | H7: 객관식 | I7: ox | K7: 수험번호 | L7: 성명 | M7: 객관식 | N7: ox | P7: 수험번호 | Q7: 성명 | R7: 객관식 | S7: ox | V7: 수험번호 | W7: 성명 | X7: 객관식
A8: 41313 | B8: 배나영 | C8: 0 | D8: 70 | F8: 18821 | G8: 최원석 | H8: 75 | I8: 0
A9: 41365 | B9: 김예지 | C9: 0 | D9: 50 | F9: 22569 | G9: 김민규 | H9: 70 | I9: 80 | K9: 41492 | L9: 김민석 | M9: 탈락 | N9: 탈락 | P9: 41492 | Q9: 김민석 | R9: 탈락 | S9: 탈락 | V9: 22569 | W9: 22569 | X9: 89
A10: 26718 | B10: 이지훈 | C10: 20 | D10: 60 | F10: 22573 | G10: 문진서 | H10: 75 | I10: 100 | K10: 41266 | L10: 남규혁 | M10: 탈락 | N10: 탈락 | P10: 41266 | Q10: 남규혁 | R10: 탈락 | S10: 탈락 | V10: 22583 | W10: 22583 | X10: 90
A11: 41343 | B11: 김어진 | C11: 20 | D11: 50 | F11: 22576 | G11: 유현민 | H11: 90 | I11: 100 | K11: 18821 | L11: 최원석 | M11: 65 | N11: 80 | P11: 18821 | Q11: 최원석 | R11: 75 | S11: 100 | V11: 22594 | W11: 22594 | X11: 54
A12: 45038 | B12: 최시영 | C12: 25 | D12: 40 | F12: 22594 | G12: 임진수 | H12: 60 | I12: 30 | K12: 22569 | L12: 김민규 | M12: 90 | N12: 90 | P12: 22569 | Q12: 김민규 | R12: 80 | S12: 70 | V12: 22838 | W12: 22838 | X12: 99
A13: 28744 | B13: 박현빈 | C13: 30 | D13: 0 | F13: 22606 | G13: 이근혁 | H13: 90 | I13: 100 | K13: 22583 | L13: 김동건 | M13: 50 | N13: 0 | P13: 22583 | Q13: 김동건 | R13: 75 | S13: 0 | V13: 23915 | W13: 23915 | X13: 70
A14: 41254 | B14: 송승아 | C14: 30 | D14: 60 | F14: 22838 | G14: 배민재 | H14: 95 | I14: 100 | K14: 22594 | L14: 임진수 | M14: 70 | N14: 40 | P14: 22594 | Q14: 임진수 | R14: 45 | S14: 60 | V14: 24108 | W14: 24108 | X14: 58
A15: 41359 | B15: 이인호 | C15: 30 | D15: 50 | F15: 23915 | G15: 김수빈 | H15: 40 | I15: 60 | K15: 22838 | L15: 배민재 | M15: 90 | N15: 100 | P15: 22838 | Q15: 배민재 | R15: 80 | S15: 80 | V15: 24270 | W15: 24270 | X15: 61
A16: 41394 | B16: 정재훈 | C16: 30 | D16: 40 | F16: 24108 | G16: 이승향 | H16: 60 | I16: 50 | K16: 23915 | L16: 김수빈 | M16: 50 | N16: 70 | P16: 23915 | Q16: 김수빈 | R16: 40 | S16: 70 | V16: 25054 | W16: 25054 | X16: 96
A17: 41460 | B17: 이채민 | C17: 30 | D17: 60 | F17: 24270 | G17: 박준우 | H17: 40 | I17: 40 | K17: 24108 | L17: 이승향 | M17: 20 | N17: 30 | P17: 24108 | Q17: 이승향 | R17: 25 | S17: 40 | V17: 25225 | W17: 25225 | X17: 39
A18: 41258 | B18: 이경훈 | C18: 35 | D18: 0 | F18: 24384 | G18: 손승효 | H18: 100 | I18: 90 | K18: 24270 | L18: 박준우 | M18: 50 | N18: 70 | P18: 24384 | Q18: 손승효 | R18: 90 | S18: 90 | V18: 25316 | W18: 25316 | X18: 90
A19: 22594 | B19: 임진수 | C19: 40 | D19: 50 | F19: 25054 | G19: 정민겸 | H19: 80 | I19: 100 | K19: 25054 | L19: 점민겸 | M19: 90 | N19: 100 | P19: 25054 | Q19: 정민검 | R19: 100 | S19: 90 | V19: 26455 | W19: 26455 | X19: 98
A20: 28705 | B20: 전민우 | C20: 40 | D20: 30 | F20: 25104 | G20: 박나현 | H20: 95 | I20: 100 | K20: 25225 | L20: 박준우 | M20: 20 | N20: 70 | P20: 25225 | Q20: 박준우 | R20: 20 | S20: 40 | V20: 26562 | W20: 26562 | X20: 95
A21: 32423 | B21: 이광훈 | C21: 40 | D21: 0 | F21: 25238 | G21: 김수진 | H21: 80 | I21: 80 | K21: 25238 | L21: 김수진 | M21: 60 | N21: 70 | P21: 25238 | Q21: 김수진 | R21: 60 | S21: 70 | V21: 26599 | W21: 26599 | X21: 93
A22: 41376 | B22: 손아림 | C22: 40 | D22: 40 | F22: 25266 | G22: 박산들 | H22: 85 | I22: 80 | K22: 25343 | L22: 이소정 | M22: 85 | N22: 90 | P22: 25343 | Q22: 이소정 | R22: 80 | S22: 80 | V22: 26657 | W22: 26657 | X22: 66
... A86: 22576 | B86: 유현민 | C86: 80 | D86: 70 | F86: 36011 | G86: 김현우 | H86: 65 | I86: 90 | K86: 36136 | L86: 안동건 | M86: 20 | N86: 0 | P86: 36140 | Q86: 최유민 | R86: 65 | S86: 80 | V86: 36170 | W86: 36170 | X86: 86
A87: 22583 | B87: 김동건 | C87: 80 | D87: 0 | F87: 36023 | H87: 65 | I87: 70 | K87: 36137 | L87: 손영현 | M87: 70 | N87: 80 | P87: 36165 | Q87: 배인영 | R87: 80 | S87: 80 | V87: 36178 | W87: 36178 | X87: 99
A88: 25316 | B88: 최원철 | C88: 80 | D88: 50 | F88: 36029 | G88: 김승원 | H88: 95 | I88: 100 | K88: 36140 | L88: 최유민 | M88: 65 | N88: 70 | P88: 36170 | Q88: 박현진 | R88: 50 | S88: 80 | V88: 36451 | W88: 36451 | X88: 96
A89: 26455 | B89: 양소은 | C89: 80 | D89: 50 | F89: 36046 | G89: 김민기 | H89: 90 | I89: 90 | K89: 36165 | L89: 배인영 | M89: 55 | N89: 70 | P89: 36178 | Q89: 김예원 | R89: 75 | S89: 80 | V89: 36718 | W89: 36718 | X89: 95
A90: 28686 | B90: 원예정 | C90: 80 | D90: 90 | F90: 36049 | G90: 정이든 | H90: 45 | I90: 100 | K90: 36170 | L90: 박현진 | M90: 55 | N90: 60 | P90: 36451 | Q90: 김싱연 | R90: 85 | S90: 90 | V90: 37128 | W90: 37128 | X90: 67
A91: 28690 | B91: 김영서 | C91: 80 | D91: 60 | F91: 36056 | G91: 김유민 | H91: 95 | I91: 100 | K91: 36178 | L91: 김예원 | M91: 95 | N91: 90 | P91: 37133 | Q91: 권성준 | R91: 75 | S91: 70 | V91: 37133 | W91: 37133 | X91: 95
A92: 28703 | B92: 정해린 | C92: 80 | D92: 50 | F92: 36062 | G92: 장민지 | H92: 85 | I92: 100 | K92: 36451 | L92: 김승연 | M92: 80 | N92: 90 | P92: 37134 | Q92: 김동규 | R92: 95 | S92: 100 | V92: 37134 | W92: 37134 | X92: 99
A93: 32677 | B93: 김윤서 | C93: 80 | D93: 40 | F93: 36065 | G93: 박수석 | H93: 90 | I93: 60 | K93: 36718 | L93: 김아현 | M93: 85 | N93: 100 | P93: 39542 | Q93: 이동언 | R93: 85 | S93: 0 | V93: 39542 | W93: 39542 | X93: 94
A94: 32684 | B94: 박준형 | C94: 80 | D94: 80 | F94: 36071 | G94: 김지윤 | H94: 80 | I94: 90 | K94: 37133 | L94: 권성준 | M94: 95 | N94: 90 | P94: 41249 | Q94: 전현우 | R94: 50 | S94: 10 | V94: 41249 | W94: 41249 | X94: 77
A95: 34568 | B95: 이주성 | C95: 80 | D95: 70 | F95: 36073 | G95: 정애림 | H95: 95 | I95: 100 | K95: 37134 | L95: 김동규 | M95: 95 | N95: 100 | P95: 41252 | Q95: 김하은 | R95: 70 | S95: 30 | V95: 41252 | W95: 41252 | X95: 92
A96: 35414 | B96: 이정연 | C96: 80 | D96: 50 | F96: 36103 | G96: 김건희 | H96: 55 | I96: 50 | K96: 39542 | L96: 이동언 | M96: 75 | N96: 90 | P96: 41254 | Q96: 송승아 | R96: 40 | S96: 30 | V96: 41254 | W96: 41254 | X96: 64
A97: 36071 | B97: 김지윤 | C97: 80 | D97: 60 | F97: 36106 | G97: 김민진 | H97: 80 | I97: 100 | K97: 41252 | L97: 김하은 | M97: 40 | N97: 0 | P97: 41268 | Q97: 박혜주 | R97: 45 | S97: 30 | V97: 41258 | W97: 41258 | X97: 66
A98: 36106 | B98: 김민진 | C98: 80 | D98: 50 | F98: 36132 | G98: 최세나 | H98: 85 | I98: 90 | K98: 41254 | L98: 송승아 | M98: 45 | N98: 40 | P98: 41273 | Q98: 고윤솔 | R98: 75 | S98: 40 | V98: 41268 | W98: 41268 | X98: 68
A99: 41273 | B99: 고윤솔 | C99: 80 | D99: 40 | F99: 36136 | G99: 안동건 | H99: 20 | I99: 0 | K99: 41268 | L99: 박혜주 | M99: 50 | N99: 70 | P99: 41274 | Q99: 장재명 | R99: 60 | S99: 60 | V99: 41273 | W99: 41273 | X99: 81
... A135: 26562 | B135: 하채영 | C135: 90 | D135: 40 | F135: 41353 | G135: 김서현 | H135: 65 | I135: 60 | K135: 41450 | L135: 김성하 | M135: 40 | N135: 0 | P135: 41494 | Q135: 김수민 | R135: 75 | S135: 80 | V135: 41450 | W135: 41450 | X135: 57
A136: 26646 | C136: 90 | D136: 60 | F136: 41359 | G136: 이인호 | H136: 30 | I136: 30 | K136: 41455 | L136: 시민경 | M136: 50 | N136: 60 | P136: 41532 | Q136: 방승환 | R136: 80 | S136: 60 | V136: 41459 | W136: 41459 | X136: 66
A137: 28700 | B137: 김대호 | C137: 90 | D137: 70 | F137: 41361 | G137: 김정윤 | H137: 70 | I137: 90 | K137: 41459 | L137: 김근영 | M137: 25 | N137: 50 | P137: 41539 | Q137: 우민우 | R137: 40 | S137: 40 | V137: 41460 | W137: 41460 | X137: 60
A138: 28713 | B138: 박정환 | C138: 90 | D138: 90 | F138: 41363 | G138: 고건호 | H138: 50 | I138: 40 | K138: 41460 | L138: 이채민 | M138: 35 | N138: 30 | P138: 42681 | Q138: 정운주 | R138: 90 | S138: 80 | V138: 41487 | W138: 41487 | X138: 71
A139: 28722 | B139: 송영서 | C139: 90 | D139: 60 | F139: 41365 | G139: 김예지 | H139: 40 | I139: 70 | K139: 41487 | L139: 김관희 | M139: 30 | N139: 60 | P139: 43354 | Q139: 구민상 | R139: 80 | S139: 50 | V139: 41490 | W139: 41490 | X139: 85
A140: 28731 | B140: 이가은 | C140: 90 | D140: 50 | F140: 41369 | G140: 손원희 | H140: 85 | I140: 90 | K140: 41490 | L140: 김대호 | M140: 45 | N140: 70 | P140: 45038 | Q140: 최시영 | R140: 35 | S140: 50 | V140: 41494 | W140: 41494 | X140: 90
A141: 32647 | B141: 정원준 | C141: 90 | D141: 70 | F141: 41371 | G141: 한준희 | H141: 50 | I141: 50 | K141: 41494 | L141: 김수민 | M141: 95 | N141: 90 | P141: 45043 | Q141: 김이레 | R141: 85 | S141: 90 | V141: 41512 | W141: 41512 | X141: 71
A142: 32676 | B142: 이종화 | C142: 90 | D142: 90 | F142: 41372 | G142: 전해람 | H142: 60 | I142: 40 | K142: 41532 | L142: 방승환 | M142: 40 | N142: 0 | P142: 45046 | Q142: 방민호 | R142: 65 | S142: 100 | V142: 42681 | W142: 42681 | X142: 98
...

Sheet 5주차
A2: 5주차 | AT2: =AR2&"(라)" -> (라) | AU2: 라이브
A4: 헌법 | F4: 형소법 | K4: 한국사2 | P4: 영어2 | U4: 형법 | Z4: 헌법 | AE4: 경찰학 | AJ4: 누적
A7: 번호 | B7: 성명 | C7: 객관식 | D7: V.T | F7: 번호 | G7: 성명 | H7: 객관식 | I7: V.T. | K7: 번호 | L7: 성명 | M7: 객관식 | N7: V.T | P7: 번호 | Q7: 성명 | R7: 객관식 | S7: V.T | U7: 번호 | V7: 성명 | W7: 객관식 | X7: V.T. | Z7: 번호 | AA7: 성명 | AB7: 객관식 | AC7: V.T. | AE7: 번호 | AF7: 성명 | AG7: 객관식 | AH7: V.T | AJ7: 번호 | AK7: 성명 | AL7: 객관식 | AM7: V.T
A8: 41343 | B8: 김어진 | C8: 탈락 | D8: 탈락 | F8: 41343 | G8: 김어진 | H8: 탈락 | I8: 탈락 | U8: 41343 | V8: 김어진 | W8: 탈락 | X8: 탈락 | AE8: 41343 | AF8: 김어진 | AG8: 탈락 | AH8: 탈락 | AJ8: 41343 | AK8: 41343 | AL8: 탈락 | AM8: 탈락
A9: 45080 | B9: 김유선 | C9: 탈락 | D9: 탈락 | F9: 45080 | G9: 김유선 | H9: 탈락 | I9: 탈락 | U9: 45080 | V9: 김유선 | W9: 탈락 | X9: 탈락 | AE9: 45080 | AF9: 김유선 | AG9: 탈락 | AH9: 탈락 | AJ9: 45080 | AK9: 45080 | AL9: 탈락 | AM9: 탈락
A10: 36665 | B10: 박예진 | C10: 탈락 | D10: 탈락 | F10: 36665 | G10: 박예진 | H10: 탈락 | I10: 탈락 | U10: 36665 | V10: 박예진 | W10: 탈락 | X10: 탈락 | AE10: 36665 | AF10: 박예진 | AG10: 탈락 | AH10: 탈락 | AJ10: 36665 | AK10: 36665 | AL10: 탈락 | AM10: 탈락
A11: 22576 | B11: 유현민 | C11: 탈락 | D11: 탈락 | F11: 22576 | G11: 유현민 | H11: 탈락 | I11: 탈락 | U11: 22576 | V11: 유현민 | W11: 탈락 | X11: 탈락 | AE11: 22576 | AF11: 유현민 | AG11: 탈락 | AH11: 탈락 | AJ11: 22576 | AK11: 22576 | AL11: 탈락 | AM11: 탈락
A12: 32807 | B12: 장윤정 | C12: 탈락 | D12: 탈락 | F12: 32807 | G12: 장윤정 | H12: 탈락 | I12: 탈락 | U12: 32807 | V12: 장윤정 | W12: 탈락 | X12: 탈락 | AE12: 32807 | AF12: 장윤정 | AG12: 탈락 | AH12: 탈락 | AJ12: 32807 | AK12: 32807 | AL12: 탈락 | AM12: 탈락
A13: 21954 | B13: 진효창 | C13: 탈락 | D13: 탈락 | F13: 21954 | G13: 진효창 | H13: 탈락 | I13: 탈락 | U13: 21954 | V13: 진효창 | W13: 탈락 | X13: 탈락 | AE13: 21954 | AF13: 진효창 | AG13: 탈락 | AH13: 탈락 | AJ13: 21954 | AK13: 21954 | AL13: 탈락 | AM13: 탈락
A14: 41492 | B14: 김민석 | C14: 탈락 | D14: 탈락 | F14: 41492 | G14: 김민석 | H14: 탈락 | I14: 탈락 | U14: 41492 | V14: 김민석 | W14: 탈락 | X14: 탈락 | AE14: 41492 | AF14: 김민석 | AG14: 탈락 | AH14: 탈락 | AJ14: 41492 | AK14: 41492 | AL14: 탈락 | AM14: 탈락
A15: 41266 | B15: 남규혁 | C15: 탈락 | D15: 탈락 | F15: 41266 | G15: 남규혁 | H15: 탈락 | I15: 탈락 | U15: 41266 | V15: 남규혁 | W15: 탈락 | X15: 탈락 | AE15: 41266 | AF15: 남규혁 | AG15: 탈락 | AH15: 탈락 | AJ15: 41266 | AK15: 41266 | AL15: 탈락 | AM15: 탈락
A16: 18821 | B16: 최원석 | C16: 95 | D16: 70
A17: 22569 | B17: 김민규 | C17: 70 | D17: 70
A18: 22583 | B18: 김동건 | C18: 80 | D18: 0
A19: 22594 | B19: 임진수 | C19: 65 | D19: 50
A20: 22838 | B20: 배민재 | C20: 90 | D20: 90
A21: 23915 | B21: 김수빈 | C21: 65 | D21: 60
A22: 24108 | B22: 이승향 | C22: 60 | D22: 30
A23: 24270 | B23: 박준우 | C23: 45 | D23: 40
A24: 25054 | B24: 정민겸 | C24: 100 | D24: 80
A25: 25104 | B25: 박나현 | C25: 90 | D25: 80
A26: 25238 | B26: 김수진 | C26: 80 | D26: 90
A27: 25266 | B27: 박산들 | C27: 90 | D27: 80
... A176: 49853 | B176: 이준섭 | C176: 60 | D176: 30
E177: 성적
A178: 36028 | B178: 오예찬 | C178: =E178&"(라)" -> 50(라) | D178: 라이브 | E178: 50
A179: 36167 | B179: 권원대 | C179: =E179&"(라)" -> 85(라) | D179: 라이브 | E179: 85
A180: 26524 | B180: 최성재 | C180: =E180&"(라)" -> 90(라) | D180: 라이브 | E180: 90
A181: 22573 | B181: 문진서 | C181: =E181&"(라)" -> 100(라) | D181: 라이브 | E181: 100
A182: 36111 | B182: 심희은 | C182: =E182&"(라)" -> 70(라) | D182: 라이브 | E182: 70
A183: 32686 | B183: 김동현 | C183: =E183&"(라)" -> 80(라) | D183: 라이브 | E183: 80
A184: 26738 | B184: 정윤석 | C184: =E184&"(라)" -> 20(라) | D184: 라이브 | E184: 20
A185: 28682 | B185: 안서진 | C185: =E185&"(라)" -> 40(라) | D185: 라이브 | E185: 40
A186: 36025 | B186: 최준하 | C186: =E186&"(라)" -> 65(라) | D186: 라이브 | E186: 65
A187: 35951 | B187: 문기환 | C187: =E187&"(라)" -> 60(라) | D187: 라이브 | E187: 60
A188: 36263 | B188: 이수진 | C188: =E188&"(라)" -> 45(라) | D188: 라이브 | E188: 45
A189: 36472 | B189: 정현지 | C189: =E189&"(라)" -> 25(라) | D189: 라이브 | E189: 25
... A242: 21860 | B242: 김봉준 | C242: =E242&"(라)" -> 15(라) | D242: 라이브 | E242: 15

Sheet 성적입력란
A2: 1주차 | Z2: 2주차 | AX2: 3주차 | BW2: 4주차 | CV2: 5주차
A4: 헌법 | F4: 형소법 | K4: 형법 | P4: 경찰학 | U4: 주간_앞 | Z4: 헌법 | AE4: 형소법 | AJ4: 형법 | AO4: 경찰학 | AT4: 누적모의고사 | AX4: 헌법 | BC4: 형소법 | BH4: 형법 | BM4: 경찰학 | BR4: 누적모의고사 | BW4: 헌법 | CB4: 형소법 | CG4: 형법 | CL4: 경찰학 | CQ4: 누적모의고사 | CV4: 한국사 | DA4: 영어 | DF4: 경찰학 | DK4: 형법 | DP4: 형소법 | DU4: 주간_앞
A5: 46028 | F5: 46029 | Z5: 45979 | AE5: 45980 | AJ5: 45982 | AO5: 45985 | AT5: 45981 | AX5: 45986 | BC5: 45987 | BH5: 45989 | BM5: 45992 | BR5: 45988 | BW5: 45993 | CB5: 45994 | CG5: 45996 | CL5: 45999 | CQ5: 45995
A7: 수험번호 | B7: 성명 | C7: 객관식 | D7: O,X | F7: 수험번호 | G7: 성명 | H7: 객관식 | I7: O,X | K7: 수험번호 | L7: 성명 | M7: 객관식 | N7: O,X | P7: 수험번호 | Q7: 성명 | R7: 객관식 | S7: O,X | U7: 수험번호 | V7: 성명 | W7: 객관식 | Z7: 수험번호 | AA7: 성명 | AB7: 객관식 | AC7: O,X | AE7: 수험번호 | AF7: 성명 | AG7: 객관식 | AH7: O,X | AJ7: 수험번호 | AK7: 성명 | AL7: 객관식 | AM7: O,X | AO7: 수험번호 | AP7: 성명 | AQ7: 객관식 | AR7: O,X | AT7: 수험번호 | AU7: 성명 | AV7: 객관식 | AX7: 수험번호 | AY7: 성명 | AZ7: 객관식 | BA7: O,X | BC7: 수험번호 | BD7: 성명 | BE7: 객관식 | BF7: O,X | BH7: 수험번호 | BI7: 성명 | BJ7: 객관식 | BK7: O,X | BM7: 수험번호 | BN7: 성명 | BO7: 객관식 | BP7: O,X | BR7: 수험번호 | BS7: 성명 | BT7: 객관식 | BW7: 수험번호 | BX7: 성명 | BY7: 객관식 | BZ7: O,X | CB7: 수험번호 | CC7: 성명 | CD7: 객관식 | CE7: O,X | CG7: 수험번호 | CH7: 성명 | CI7: 객관식 | CJ7: O,X | CL7: 수험번호 | CM7: 성명 | CN7: 객관식 | CO7: O,X | CQ7: 수험번호 | CR7: 성명 | CS7: 객관식 | CV7: 수험번호 | CW7: 성명 | CX7: 객관식 | CY7: O,X | DA7: 수험번호 | DB7: 성명 | DC7: 객관식 | DD7: O,X | DF7: 수험번호 | DG7: 성명 | DH7: 객관식 | DI7: O,X | DK7: 수험번호 | DL7: 성명 | DM7: 객관식 | DN7: O,X | DP7: 수험번호 | DQ7: 성명 | DR7: 객관식 | DS7: O,X | DU7: 수험번호 | DV7: 성명 | DW7: 객관식 | DX7: O,X
A8: =수강생명단!$C4 -> 35357 | B8: =수강생명단!D4 -> 강건욱 | C8: =IFERROR(IF(VLOOKUP($A8,'1주차'!$A$5:$D$393,3,FALSE)="","",VLOOKUP($A8,'1주차'!$A$5:$D$393,3,FALSE)),"") -> 90(라) | D8: =IFERROR(IF(VLOOKUP($Q8,'1주차'!$A$5:$D$393,4,FALSE)="","",VLOOKUP($B8,'1주차'!$Q$5:$S$393,3,FALSE)),"") | F8: =수강생명단!C4 -> 35357 | G8: =수강생명단!D4 -> 강건욱 | H8: =IFERROR(IF(VLOOKUP($F8,'1주차'!$F$5:$I$393,3,FALSE)="","",VLOOKUP($F8,'1주차'!$F$5:$I$393,3,FALSE)),"") -> 95(라) | I8: =IFERROR(IF(VLOOKUP($Q8,'1주차'!$F$5:$I$393,3,FALSE)="","",VLOOKUP($B8,'1주차'!$Q$5:$S$393,3,FALSE)),"") | K8: =수강생명단!C4 -> 35357 | L8: =수강생명단!D4 -> 강건욱 | M8: =IFERROR(IF(VLOOKUP($K8,'1주차'!$K$5:$N$393,3,FALSE)="","",VLOOKUP($K8,'1주차'!$K$5:$N$393,3,FALSE)),"") -> 95(라) | N8: =IFERROR(IF(VLOOKUP($Q8,'1주차'!$N$5:$KQ$393,3,FALSE)="","",VLOOKUP($B8,'1주차'!$Q$5:$S$393,3,FALSE)),"") | P8: =수강생명단!C4 -> 35357 | Q8: =수강생명단!D4 -> 강건욱 | R8: =IFERROR(IF(VLOOKUP($P8,'1주차'!$P$5:$S$393,3,FALSE)="","",VLOOKUP($P8,'1주차'!$P$5:$S$393,3,FALSE)),"") -> 85(라) | S8: =IFERROR(IF(VLOOKUP($P8,'1주차'!$P$5:$S$393,4,FALSE)="","",VLOOKUP($P8,'1주차'!$P$5:$S$393,4,FALSE)),"") -> 라이브 | U8: =수강생명단!C4 -> 35357 | V8: =수강생명단!D4 -> 강건욱 | Z8: =수강생명단!$C4 -> 35357 | AA8: =수강생명단!D4 -> 강건욱 | AB8: =IFERROR(IF(VLOOKUP($A8,'2주차'!$A$5:$D$406,3,FALSE)="","",VLOOKUP($A8,'2주차'!$A$5:$D$406,3,FALSE)),"") | AC8: =IFERROR(VLOOKUP($Z8,'2주차'!$A$5:$D$400,4,FALSE)," ") | AE8: =수강생명단!$C4 -> 35357 | AF8: =수강생명단!D4 -> 강건욱 | AG8: =IFERROR(IF(VLOOKUP($AE8,'2주차'!$F$5:$I$406,3,FALSE)="","",VLOOKUP($F8,'2주차'!$F$5:$I$406,3,FALSE)),"") -> 95(라) | AH8: =IFERROR(VLOOKUP($AE8,'2주차'!$F$5:$I$400,4,FALSE)," ") -> 라이브 | AJ8: =수강생명단!$C4 -> 35357 | AK8: =수강생명단!D4 -> 강건욱 | AL8: =IFERROR(IF(VLOOKUP($AJ8,'2주차'!$U$5:$X$406,3,FALSE)="","",VLOOKUP($F8,'2주차'!$U$5:$X$406,3,FALSE)),"") -> 75(라) | AM8: =IFERROR(VLOOKUP($AJ8,'2주차'!$U$5:$X$400,4,FALSE)," ") -> 라이브 | AO8: =수강생명단!$C4 -> 35357 | AP8: =수강생명단!D4 -> 강건욱 | AQ8: =IFERROR(IF(VLOOKUP($AO8,'2주차'!$Z$5:$AC$406,3,FALSE)="","",VLOOKUP($AO8,'2주차'!$Z$5:$AC$406,3,FALSE)),"") -> 0(라) | AR8: =IFERROR(VLOOKUP($AO8,'2주차'!$Z$5:$AC$400,4,FALSE)," ") -> 라이브 | AT8: =수강생명단!$C4 -> 35357 | AU8: =수강생명단!C4 -> 35357 | AV8: =IFERROR(IF(VLOOKUP($AU8,'2주차'!$AF$5:$AI$406,3,FALSE)="","",VLOOKUP($AU8,'2주차'!$AF$5:$AI$406,3,FALSE)),"") | AX8: =수강생명단!$C4 -> 35357 | AY8: =수강생명단!D4 -> 강건욱 | AZ8: =IFERROR(IF(VLOOKUP($A8,'3주차'!$A$5:$D$406,3,FALSE)="","",VLOOKUP($A8,'3주차'!$A$5:$D$406,3,FALSE)),"") -> 80(라) | BA8: =IFERROR(VLOOKUP($Z8,'3주차'!$A$5:$D$400,4,FALSE)," ") -> 라이브 | BC8: =수강생명단!$C4 -> 35357 | BD8: =수강생명단!D4 -> 강건욱 | BE8: =IFERROR(IF(VLOOKUP($BC8,'3주차'!$F$5:$I$406,3,FALSE)="","",VLOOKUP($F8,'3주차'!$F$5:$I$406,3,FALSE)),"") -> 85(라) | BF8: =IFERROR(VLOOKUP($BC8,'3주차'!$F$5:$I$400,4,FALSE)," ") -> 라이브 | BH8: =수강생명단!$C4 -> 35357 | BI8: =수강생명단!D4 -> 강건욱 | BJ8: =IFERROR(IF(VLOOKUP($BH8,'3주차'!$K$5:$N$406,3,FALSE)="","",VLOOKUP($AJ8,'3주차'!$K$5:$XN$406,3,FALSE)),"") -> 100(라) | BK8: =IFERROR(VLOOKUP($BH8,'3주차'!$K$5:$N$400,4,FALSE)," ") -> 라이브 | BM8: =수강생명단!$C4 -> 35357 | BN8: =수강생명단!D4 -> 강건욱 | BO8: =IFERROR(IF(VLOOKUP($BM8,'3주차'!$P$5:$S$406,3,FALSE)="","",VLOOKUP($BM8,'3주차'!$P$5:$S$406,3,FALSE)),"") -> 70(라) | BP8: =IFERROR(VLOOKUP($BM8,'3주차'!$P$5:$S$400,4,FALSE)," ") -> 라이브 | BR8: =수강생명단!$C4 -> 35357 | BS8: =수강생명단!C4 -> 35357 | BT8: =IFERROR(IF(VLOOKUP($BS8,'3주차'!$V$5:$X$406,3,FALSE)="","",VLOOKUP($BS8,'3주차'!$V$5:$X$406,3,FALSE)),"") | BW8: =수강생명단!$C4 -> 35357 | BX8: =수강생명단!D4 -> 강건욱 | BY8: =IFERROR(IF(VLOOKUP($A8,'4주차'!$A$5:$D$406,3,FALSE)="","",VLOOKUP($A8,'4주차'!$A$5:$D$406,3,FALSE)),"") | BZ8: =IFERROR(VLOOKUP($Z8,'4주차'!$A$5:$D$400,4,FALSE)," ") | CB8: =수강생명단!$C4 -> 35357 | CC8: =수강생명단!D4 -> 강건욱 | CD8: =IFERROR(IF(VLOOKUP($BC8,'4주차'!$F$5:$I$406,3,FALSE)="","",VLOOKUP($F8,'4주차'!$F$5:$I$406,3,FALSE)),"") | CE8: =IFERROR(VLOOKUP($BC8,'4주차'!$F$5:$I$400,4,FALSE)," ") | CG8: =수강생명단!$C4 -> 35357 | CH8: =수강생명단!D4 -> 강건욱 | CI8: =IFERROR(IF(VLOOKUP($BH8,'4주차'!$K$5:$N$406,3,FALSE)="","",VLOOKUP($AJ8,'4주차'!$K$5:$WU$406,3,FALSE)),"") -> 95(라) | CJ8: =IFERROR(VLOOKUP($BH8,'4주차'!$K$5:$N$400,4,FALSE)," ") -> 라이브 | CL8: =수강생명단!$C4 -> 35357 | CM8: =수강생명단!D4 -> 강건욱 | CN8: =IFERROR(IF(VLOOKUP($BM8,'4주차'!$P$5:$S$406,3,FALSE)="","",VLOOKUP($BM8,'4주차'!$P$5:$S$406,3,FALSE)),"") -> 5(라) | CO8: =IFERROR(VLOOKUP($BM8,'4주차'!$P$5:$S$400,4,FALSE)," ") -> 라이브 | CQ8: =수강생명단!$C4 -> 35357 | CR8: =수강생명단!C4 -> 35357 | CS8: =IFERROR(IF(VLOOKUP($BS8,'4주차'!$V$5:$X$406,3,FALSE)="","",VLOOKUP($BS8,'4주차'!$V$5:$X$406,3,FALSE)),"") -> 0(라) | CV8: 1 | CW8: =수강생명단!D4 -> 강건욱 | CX8: =IFERROR(VLOOKUP($BX8,'5주차'!$B$5:$D$400,2,FALSE),"불참") -> 0(라) | CY8: =IFERROR(VLOOKUP($AY8,'5주차'!$B$5:$D$400,3,FALSE),"불참") -> 라이브 | DA8: 1 | DB8: =수강생명단!D4 -> 강건욱 | DC8: =IFERROR(VLOOKUP($CC8,'5주차'!$G$5:$I$400,2,FALSE),"불참") -> 불참 | DD8: =IFERROR(VLOOKUP($CC8,'5주차'!$G$5:$I$400,3,FALSE),"불참") -> 불참 | DF8: 1 | DG8: =수강생명단!D4 -> 강건욱 | DH8: =IFERROR(VLOOKUP($CH8,'5주차'!$V$5:$X$400,2,FALSE),"불참") -> 불참 | DI8: =IFERROR(VLOOKUP($BI8,'5주차'!$V$5:$X$400,3,FALSE),"불참") -> 불참 | DK8: 1 | DL8: =수강생명단!D4 -> 강건욱 | DM8: =IFERROR(VLOOKUP($CM8,'5주차'!$AA$5:$AC$400,2,FALSE),"불참") -> 불참 | DN8: =IFERROR(VLOOKUP($CM8,'5주차'!$AA$5:$AC$400,3,FALSE),"불참") -> 불참 | DP8: 1 | DQ8: =수강생명단!D4 -> 강건욱 | DR8: =IFERROR(VLOOKUP(#REF!,'5주차'!$AF$5:$AH$400,2,FALSE),"불참") -> 불참 | DS8: =IFERROR(VLOOKUP(#REF!,'5주차'!$AF$5:$AH$400,3,FALSE),"불참") -> 불참 | DU8: 1 | DV8: =수강생명단!C4 -> 35357 | DW8: =IFERROR(VLOOKUP($DV8,'5주차'!$AK$5:$AL$400,2,FALSE),"불참") -> 불참 | DX8: =IFERROR(VLOOKUP($DV8,'5주차'!$AK$5:$AL$400,2,FALSE),"불참") -> 불참
A9: =수강생명단!$C5 -> 33596 | B9: =수강생명단!D5 -> 강동우 | C9: =IFERROR(IF(VLOOKUP($A9,'1주차'!$A$5:$D$393,3,FALSE)="","",VLOOKUP($A9,'1주차'!$A$5:$D$393,3,FALSE)),"") -> 95 | D9: =IFERROR(IF(VLOOKUP($Q9,'1주차'!$A$5:$D$393,4,FALSE)="","",VLOOKUP($B9,'1주차'!$Q$5:$S$393,3,FALSE)),"") | F9: =수강생명단!C5 -> 33596 | G9: =수강생명단!D5 -> 강동우 | H9: =IFERROR(IF(VLOOKUP($F9,'1주차'!$F$5:$I$393,3,FALSE)="","",VLOOKUP($F9,'1주차'!$F$5:$I$393,3,FALSE)),"") -> 95 | I9: =IFERROR(IF(VLOOKUP($Q9,'1주차'!$F$5:$I$393,3,FALSE)="","",VLOOKUP($B9,'1주차'!$Q$5:$S$393,3,FALSE)),"") | K9: =수강생명단!C5 -> 33596 | L9: =수강생명단!D5 -> 강동우 | M9: =IFERROR(IF(VLOOKUP($K9,'1주차'!$K$5:$N$393,3,FALSE)="","",VLOOKUP($K9,'1주차'!$K$5:$N$393,3,FALSE)),"") -> 95 | N9: =IFERROR(IF(VLOOKUP($Q9,'1주차'!$N$5:$KQ$393,3,FALSE)="","",VLOOKUP($B9,'1주차'!$Q$5:$S$393,3,FALSE)),"") | P9: =수강생명단!C5 -> 33596 | Q9: =수강생명단!D5 -> 강동우 | R9: =IFERROR(IF(VLOOKUP($P9,'1주차'!$P$5:$S$393,3,FALSE)="","",VLOOKUP($P9,'1주차'!$P$5:$S$393,3,FALSE)),"") -> 100 | S9: =IFERROR(IF(VLOOKUP($P9,'1주차'!$P$5:$S$393,4,FALSE)="","",VLOOKUP($P9,'1주차'!$P$5:$S$393,4,FALSE)),"") -> 100 | U9: =수강생명단!C5 -> 33596 | V9: =수강생명단!D5 -> 강동우 | Z9: =수강생명단!$C5 -> 33596 | AA9: =수강생명단!D5 -> 강동우 | AB9: =IFERROR(IF(VLOOKUP($A9,'2주차'!$A$5:$D$406,3,FALSE)="","",VLOOKUP($A9,'2주차'!$A$5:$D$406,3,FALSE)),"") -> 100 | AC9: =IFERROR(VLOOKUP($Z9,'2주차'!$A$5:$D$400,4,FALSE)," ") -> 100 | AE9: =수강생명단!$C5 -> 33596 | AF9: =수강생명단!D5 -> 강동우 | AG9: =IFERROR(IF(VLOOKUP($AE9,'2주차'!$F$5:$I$406,3,FALSE)="","",VLOOKUP($F9,'2주차'!$F$5:$I$406,3,FALSE)),"") -> 95 | AH9: =IFERROR(VLOOKUP($AE9,'2주차'!$F$5:$I$400,4,FALSE)," ") -> 100 | AJ9: =수강생명단!$C5 -> 33596 | AK9: =수강생명단!D5 -> 강동우 | AL9: =IFERROR(IF(VLOOKUP($AJ9,'2주차'!$U$5:$X$406,3,FALSE)="","",VLOOKUP($F9,'2주차'!$U$5:$X$406,3,FALSE)),"") -> 95 | AM9: =IFERROR(VLOOKUP($AJ9,'2주차'!$U$5:$X$400,4,FALSE)," ") -> 100 | AO9: =수강생명단!$C5 -> 33596 | AP9: =수강생명단!D5 -> 강동우 | AQ9: =IFERROR(IF(VLOOKUP($AO9,'2주차'!$Z$5:$AC$406,3,FALSE)="","",VLOOKUP($AO9,'2주차'!$Z$5:$AC$406,3,FALSE)),"") -> 95 | AR9: =IFERROR(VLOOKUP($AO9,'2주차'!$Z$5:$AC$400,4,FALSE)," ") -> 90 | AT9: =수강생명단!$C5 -> 33596 | AU9: =수강생명단!C5 -> 33596 | AV9: =IFERROR(IF(VLOOKUP($AU9,'2주차'!$AF$5:$AI$406,3,FALSE)="","",VLOOKUP($AU9,'2주차'!$AF$5:$AI$406,3,FALSE)),"") -> 99 | AX9: =수강생명단!$C5 -> 33596 | AY9: =수강생명단!D5 -> 강동우 | AZ9: =IFERROR(IF(VLOOKUP($A9,'3주차'!$A$5:$D$406,3,FALSE)="","",VLOOKUP($A9,'3주차'!$A$5:$D$406,3,FALSE)),"") -> 90 | BA9: =IFERROR(VLOOKUP($Z9,'3주차'!$A$5:$D$400,4,FALSE)," ") -> 100 | BC9: =수강생명단!$C5 -> 33596 | BD9: =수강생명단!D5 -> 강동우 | BE9: =IFERROR(IF(VLOOKUP($BC9,'3주차'!$F$5:$I$406,3,FALSE)="","",VLOOKUP($F9,'3주차'!$F$5:$I$406,3,FALSE)),"") -> 95 | BF9: =IFERROR(VLOOKUP($BC9,'3주차'!$F$5:$I$400,4,FALSE)," ") -> 100 | BH9: =수강생명단!$C5 -> 33596 | BI9: =수강생명단!D5 -> 강동우 | BJ9: =IFERROR(IF(VLOOKUP($BH9,'3주차'!$K$5:$N$406,3,FALSE)="","",VLOOKUP($AJ9,'3주차'!$K$5:$XN$406,3,FALSE)),"") -> 100 | BK9: =IFERROR(VLOOKUP($BH9,'3주차'!$K$5:$N$400,4,FALSE)," ") -> 100 | BM9: =수강생명단!$C5 -> 33596 | BN9: =수강생명단!D5 -> 강동우 | BO9: =IFERROR(IF(VLOOKUP($BM9,'3주차'!$P$5:$S$406,3,FALSE)="","",VLOOKUP($BM9,'3주차'!$P$5:$S$406,3,FALSE)),"") -> 100 | BP9: =IFERROR(VLOOKUP($BM9,'3주차'!$P$5:$S$400,4,FALSE)," ") -> 100 | BR9: =수강생명단!$C5 -> 33596 | BS9: =수강생명단!C5 -> 33596 | BT9: =IFERROR(IF(VLOOKUP($BS9,'3주차'!$V$5:$X$406,3,FALSE)="","",VLOOKUP($BS9,'3주차'!$V$5:$X$406,3,FALSE)),"") -> 99 | BW9: =수강생명단!$C5 -> 33596 | BX9: =수강생명단!D5 -> 강동우 | BY9: =IFERROR(IF(VLOOKUP($A9,'4주차'!$A$5:$D$406,3,FALSE)="","",VLOOKUP($A9,'4주차'!$A$5:$D$406,3,FALSE)),"") -> 90 | BZ9: =IFERROR(VLOOKUP($Z9,'4주차'!$A$5:$D$400,4,FALSE)," ") -> 90 | CB9: =수강생명단!$C5 -> 33596 | CC9: =수강생명단!D5 -> 강동우 | CD9: =IFERROR(IF(VLOOKUP($BC9,'4주차'!$F$5:$I$406,3,FALSE)="","",VLOOKUP($F9,'4주차'!$F$5:$I$406,3,FALSE)),"") -> 100 | CE9: =IFERROR(VLOOKUP($BC9,'4주차'!$F$5:$I$400,4,FALSE)," ") -> 100 | CG9: =수강생명단!$C5 -> 33596 | CH9: =수강생명단!D5 -> 강동우 | CI9: =IFERROR(IF(VLOOKUP($BH9,'4주차'!$K$5:$N$406,3,FALSE)="","",VLOOKUP($AJ9,'4주차'!$K$5:$WU$406,3,FALSE)),"") -> 90 | CJ9: =IFERROR(VLOOKUP($BH9,'4주차'!$K$5:$N$400,4,FALSE)," ") -> 100 | CL9: =수강생명단!$C5 -> 33596 | CM9: =수강생명단!D5 -> 강동우 | CN9: =IFERROR(IF(VLOOKUP($BM9,'4주차'!$P$5:$S$406,3,FALSE)="","",VLOOKUP($BM9,'4주차'!$P$5:$S$406,3,FALSE)),"") -> 95 | CO9: =IFERROR(VLOOKUP($BM9,'4주차'!$P$5:$S$400,4,FALSE)," ") -> 100 | CQ9: =수강생명단!$C5 -> 33596 | CR9: =수강생명단!C5 -> 33596 | CS9: =IFERROR(IF(VLOOKUP($BS9,'4주차'!$V$5:$X$406,3,FALSE)="","",VLOOKUP($BS9,'4주차'!$V$5:$X$406,3,FALSE)),"") -> 100 | CV9: 2 | CW9: =수강생명단!D5 -> 강동우 | CX9: =IFERROR(VLOOKUP($BX9,'5주차'!$B$5:$D$400,2,FALSE),"불참") -> 95 | CY9: =IFERROR(VLOOKUP($AY9,'5주차'!$B$5:$D$400,3,FALSE),"불참") -> 100 | DA9: 2 | DB9: =수강생명단!D5 -> 강동우 | DC9: =IFERROR(VLOOKUP($CC9,'5주차'!$G$5:$I$400,2,FALSE),"불참") -> 불참 | DD9: =IFERROR(VLOOKUP($CC9,'5주차'!$G$5:$I$400,3,FALSE),"불참") -> 불참 | DF9: 2 | DG9: =수강생명단!D5 -> 강동우 | DH9: =IFERROR(VLOOKUP($CH9,'5주차'!$V$5:$X$400,2,FALSE),"불참") -> 불참 | DI9: =IFERROR(VLOOKUP($BI9,'5주차'!$V$5:$X$400,3,FALSE),"불참") -> 불참 | DK9: 2 | DL9: =수강생명단!D5 -> 강동우 | DM9: =IFERROR(VLOOKUP($CM9,'5주차'!$AA$5:$AC$400,2,FALSE),"불참") -> 불참 | DN9: =IFERROR(VLOOKUP($CM9,'5주차'!$AA$5:$AC$400,3,FALSE),"불참") -> 불참 | DP9: 2 | DQ9: =수강생명단!D5 -> 강동우 | DR9: =IFERROR(VLOOKUP(#REF!,'5주차'!$AF$5:$AH$400,2,FALSE),"불참") -> 불참 | DS9: =IFERROR(VLOOKUP(#REF!,'5주차'!$AF$5:$AH$400,3,FALSE),"불참") -> 불참 | DU9: 2 | DV9: =수강생명단!C5 -> 33596 | DW9: =IFERROR(VLOOKUP($DV9,'5주차'!$AK$5:$AL$400,2,FALSE),"불참") -> 불참 | DX9: =IFERROR(VLOOKUP($DV9,'5주차'!$AK$5:$AL$400,2,FALSE),"불참") -> 불참
